Workbook

Sheet ReadMe
A1: Cerdik Tuition Centre 补习中心 · Jul–Sep 2026 records (invented practice data)
A3: What this is | B3: Records of an invented tuition centre, to test whether the dashboard can read an Excel with a different structure. All names, phone numbers and figures are invented.
A4: Period | B4: Invoices for July, August and September 2026 (issued on the 1st, due on the 7th). Receipts and classes up to 24 September 2026.
A5: Students | B5: One row per student: level, date joined, status (Active / Paused / Left).
A6: Invoices | B6: One row per monthly invoice. Invoice Total, Amount Paid, Balance and Status are formulas: the total adds up the invoice lines, the amount paid adds up the receipts. Type Yes under Void to cancel an invoice.
A7: Invoice Lines | B7: One row per subject (and a one-off registration fee for new students). Line Total = Qty × Unit Fee (formula). Edit Qty or Unit Fee; the totals follow.
A8: Receipts | B8: One row per payment received, linked to an invoice. Some September invoices are unpaid or half paid.
A9: Classes | B9: September class sessions with enrolled and present counts — a kind of record the BetterSpace layout does not have.
A10: Different from BetterSpace | B10: Services, not products: no stock sheet. An invoice is made of several lines. Invoice status means payment status (Issued / Partially Paid / Paid / Void), not delivery. Extra Classes sheet. Different sheet and column names.

Sheet Students
A1: Student No | B1: Student Name | C1: Parent Name | D1: Parent Phone | E1: Level | F1: Joined On | G1: Status
A2: S1001 | B2: Isaac Tan | C2: Parent of Isaac | D2: 014-555 8115 | E2: Std 4 | F2: 46263 | G2: Active
A3: S1002 | B3: Ooi Kai Xuan | C3: Parent of Ooi | D3: 014-555 8903 | E3: Form 1 | F3: 45794 | G3: Active
A4: S1003 | B4: Tan Wei Ming | C4: Parent of Tan | D4: 014-555 5652 | E4: Form 5 | F4: 45830 | G4: Active
A5: S1004 | B5: Teoh Mei Qi | C5: Parent of Teoh | D5: 012-555 1463 | E5: Form 1 | F5: 46007 | G5: Active
A6: S1005 | B6: Sofia Lim | C6: Parent of Sofia | D6: 013-555 6549 | E6: Form 5 | F6: 45842 | G6: Active
A7: S1006 | B7: Nadia Wong | C7: Parent of Nadia | D7: 016-555 3805 | E7: Std 6 | F7: 45858 | G7: Active
A8: S1007 | B8: Chong Zi Yang | C8: Parent of Chong | D8: 013-555 5736 | E8: Form 2 | F8: 46102 | G8: Active
A9: S1008 | B9: Kyle Lee | C9: Parent of Kyle | D9: 016-555 6491 | E9: Std 4 | F9: 45889 | G9: Active
A10: S1009 | B10: Isaac Wong | C10: Parent of Isaac | D10: 016-555 4186 | E10: Std 4 | F10: 46023 | G10: Active
A11: S1010 | B11: Adam Harith | C11: Parent of Adam | D11: 012-555 9418 | E11: Std 4 | F11: 46098 | G11: Left
A12: S1011 | B12: Aiden Tan | C12: Parent of Aiden | D12: 016-555 9920 | E12: Form 2 | F12: 45912 | G12: Active
A13: S1012 | B13: Chloe Lee | C13: Parent of Chloe | D13: 013-555 6366 | E13: Form 5 | F13: 46009 | G13: Active
... A57: S1056 | B57: Shalini Devi | C57: Parent of Shalini | D57: 019-555 1088 | E57: Form 5 | F57: 45942 | G57: Paused

Sheet Invoices
A1: Invoice No | B1: Student No | C1: Invoice Date | D1: Due Date | E1: Void | F1: Invoice Total | G1: Amount Paid | H1: Balance | I1: Status
A2: INV-2607-001 | B2: S1002 | C2: 46204 | D2: 46210 | F2: =SUMIFS('Invoice Lines'!$G$2:$G$319,'Invoice Lines'!$A$2:$A$319,A2) -> 300 | G2: =SUMIFS(Receipts!$D$2:$D$149,Receipts!$B$2:$B$149,A2) -> 300 | H2: =IF(E2="Yes",0,F2-G2) -> 0 | I2: =IF(E2="Yes","Void",IF(H2<=0,"Paid",IF(G2>0,"Partially Paid","Issued"))) -> Paid
A3: INV-2607-002 | B3: S1003 | C3: 46204 | D3: 46210 | F3: =SUMIFS('Invoice Lines'!$G$2:$G$319,'Invoice Lines'!$A$2:$A$319,A3) -> 180 | G3: =SUMIFS(Receipts!$D$2:$D$149,Receipts!$B$2:$B$149,A3) -> 180 | H3: =IF(E3="Yes",0,F3-G3) -> 0 | I3: =IF(E3="Yes","Void",IF(H3<=0,"Paid",IF(G3>0,"Partially Paid","Issued"))) -> Paid
A4: INV-2607-003 | B4: S1004 | C4: 46204 | D4: 46210 | F4: =SUMIFS('Invoice Lines'!$G$2:$G$319,'Invoice Lines'!$A$2:$A$319,A4) -> 300 | G4: =SUMIFS(Receipts!$D$2:$D$149,Receipts!$B$2:$B$149,A4) -> 300 | H4: =IF(E4="Yes",0,F4-G4) -> 0 | I4: =IF(E4="Yes","Void",IF(H4<=0,"Paid",IF(G4>0,"Partially Paid","Issued"))) -> Paid
A5: INV-2607-004 | B5: S1005 | C5: 46204 | D5: 46210 | F5: =SUMIFS('Invoice Lines'!$G$2:$G$319,'Invoice Lines'!$A$2:$A$319,A5) -> 180 | G5: =SUMIFS(Receipts!$D$2:$D$149,Receipts!$B$2:$B$149,A5) -> 180 | H5: =IF(E5="Yes",0,F5-G5) -> 0 | I5: =IF(E5="Yes","Void",IF(H5<=0,"Paid",IF(G5>0,"Partially Paid","Issued"))) -> Paid
A6: INV-2607-005 | B6: S1006 | C6: 46204 | D6: 46210 | F6: =SUMIFS('Invoice Lines'!$G$2:$G$319,'Invoice Lines'!$A$2:$A$319,A6) -> 240 | G6: =SUMIFS(Receipts!$D$2:$D$149,Receipts!$B$2:$B$149,A6) -> 240 | H6: =IF(E6="Yes",0,F6-G6) -> 0 | I6: =IF(E6="Yes","Void",IF(H6<=0,"Paid",IF(G6>0,"Partially Paid","Issued"))) -> Paid
A7: INV-2607-006 | B7: S1007 | C7: 46204 | D7: 46210 | F7: =SUMIFS('Invoice Lines'!$G$2:$G$319,'Invoice Lines'!$A$2:$A$319,A7) -> 150 | G7: =SUMIFS(Receipts!$D$2:$D$149,Receipts!$B$2:$B$149,A7) -> 150 | H7: =IF(E7="Yes",0,F7-G7) -> 0 | I7: =IF(E7="Yes","Void",IF(H7<=0,"Paid",IF(G7>0,"Partially Paid","Issued"))) -> Paid
A8: INV-2607-007 | B8: S1008 | C8: 46204 | D8: 46210 | F8: =SUMIFS('Invoice Lines'!$G$2:$G$319,'Invoice Lines'!$A$2:$A$319,A8) -> 120 | G8: =SUMIFS(Receipts!$D$2:$D$149,Receipts!$B$2:$B$149,A8) -> 120 | H8: =IF(E8="Yes",0,F8-G8) -> 0 | I8: =IF(E8="Yes","Void",IF(H8<=0,"Paid",IF(G8>0,"Partially Paid","Issued"))) -> Paid
A9: INV-2607-008 | B9: S1009 | C9: 46204 | D9: 46210 | F9: =SUMIFS('Invoice Lines'!$G$2:$G$319,'Invoice Lines'!$A$2:$A$319,A9) -> 240 | G9: =SUMIFS(Receipts!$D$2:$D$149,Receipts!$B$2:$B$149,A9) -> 240 | H9: =IF(E9="Yes",0,F9-G9) -> 0 | I9: =IF(E9="Yes","Void",IF(H9<=0,"Paid",IF(G9>0,"Partially Paid","Issued"))) -> Paid
A10: INV-2607-009 | B10: S1010 | C10: 46204 | D10: 46210 | F10: =SUMIFS('Invoice Lines'!$G$2:$G$319,'Invoice Lines'!$A$2:$A$319,A10) -> 360 | G10: =SUMIFS(Receipts!$D$2:$D$149,Receipts!$B$2:$B$149,A10) -> 360 | H10: =IF(E10="Yes",0,F10-G10) -> 0 | I10: =IF(E10="Yes","Void",IF(H10<=0,"Paid",IF(G10>0,"Partially Paid","Issued"))) -> Paid
A11: INV-2607-010 | B11: S1011 | C11: 46204 | D11: 46210 | F11: =SUMIFS('Invoice Lines'!$G$2:$G$319,'Invoice Lines'!$A$2:$A$319,A11) -> 150 | G11: =SUMIFS(Receipts!$D$2:$D$149,Receipts!$B$2:$B$149,A11) -> 150 | H11: =IF(E11="Yes",0,F11-G11) -> 0 | I11: =IF(E11="Yes","Void",IF(H11<=0,"Paid",IF(G11>0,"Partially Paid","Issued"))) -> Paid
A12: INV-2607-011 | B12: S1012 | C12: 46204 | D12: 46210 | F12: =SUMIFS('Invoice Lines'!$G$2:$G$319,'Invoice Lines'!$A$2:$A$319,A12) -> 540 | G12: =SUMIFS(Receipts!$D$2:$D$149,Receipts!$B$2:$B$149,A12) -> 540 | H12: =IF(E12="Yes",0,F12-G12) -> 0 | I12: =IF(E12="Yes","Void",IF(H12<=0,"Paid",IF(G12>0,"Partially Paid","Issued"))) -> Paid
A13: INV-2607-012 | B13: S1014 | C13: 46204 | D13: 46210 | F13: =SUMIFS('Invoice Lines'!$G$2:$G$319,'Invoice Lines'!$A$2:$A$319,A13) -> 360 | G13: =SUMIFS(Receipts!$D$2:$D$149,Receipts!$B$2:$B$149,A13) -> 360 | H13: =IF(E13="Yes",0,F13-G13) -> 0 | I13: =IF(E13="Yes","Void",IF(H13<=0,"Paid",IF(G13>0,"Partially Paid","Issued"))) -> Paid
... A116: INV-2609-009 | B116: S1009 | C116: 46266 | D116: 46272 | F116: =SUMIFS('Invoice Lines'!$G$2:$G$319,'Invoice Lines'!$A$2:$A$319,A116) -> 240 | G116: =SUMIFS(Receipts!$D$2:$D$149,Receipts!$B$2:$B$149,A116) -> 240 | H116: =IF(E116="Yes",0,F116-G116) -> 0 | I116: =IF(E116="Yes","Void",IF(H116<=0,"Paid",IF(G116>0,"Partially Paid","Issued"))) -> Paid
A117: INV-2609-010 | B117: S1010 | C117: 46266 | D117: 46272 | E117: Yes | F117: =SUMIFS('Invoice Lines'!$G$2:$G$319,'Invoice Lines'!$A$2:$A$319,A117) -> 360 | G117: =SUMIFS(Receipts!$D$2:$D$149,Receipts!$B$2:$B$149,A117) -> 0 | H117: =IF(E117="Yes",0,F117-G117) -> 0 | I117: =IF(E117="Yes","Void",IF(H117<=0,"Paid",IF(G117>0,"Partially Paid","Issued"))) -> Void
A118: INV-2609-011 | B118: S1011 | C118: 46266 | D118: 46272 | F118: =SUMIFS('Invoice Lines'!$G$2:$G$319,'Invoice Lines'!$A$2:$A$319,A118) -> 150 | G118: =SUMIFS(Receipts!$D$2:$D$149,Receipts!$B$2:$B$149,A118) -> 150 | H118: =IF(E118="Yes",0,F118-G118) -> 0 | I118: =IF(E118="Yes","Void",IF(H118<=0,"Paid",IF(G118>0,"Partially Paid","Issued"))) -> Paid
A119: INV-2609-012 | B119: S1012 | C119: 46266 | D119: 46272 | F119: =SUMIFS('Invoice Lines'!$G$2:$G$319,'Invoice Lines'!$A$2:$A$319,A119) -> 540 | G119: =SUMIFS(Receipts!$D$2:$D$149,Receipts!$B$2:$B$149,A119) -> 0 | H119: =IF(E119="Yes",0,F119-G119) -> 540 | I119: =IF(E119="Yes","Void",IF(H119<=0,"Paid",IF(G119>0,"Partially Paid","Issued"))) -> Issued
A120: INV-2609-013 | B120: S1013 | C120: 46266 | D120: 46272 | F120: =SUMIFS('Invoice Lines'!$G$2:$G$319,'Invoice Lines'!$A$2:$A$319,A120) -> 290 | G120: =SUMIFS(Receipts!$D$2:$D$149,Receipts!$B$2:$B$149,A120) -> 290 | H120: =IF(E120="Yes",0,F120-G120) -> 0 | I120: =IF(E120="Yes","Void",IF(H120<=0,"Paid",IF(G120>0,"Partially Paid","Issued"))) -> Paid
A121: INV-2609-014 | B121: S1014 | C121: 46266 | D121: 46272 | F121: =SUMIFS('Invoice Lines'!$G$2:$G$319,'Invoice Lines'!$A$2:$A$319,A121) -> 360 | G121: =SUMIFS(Receipts!$D$2:$D$149,Receipts!$B$2:$B$149,A121) -> 360 | H121: =IF(E121="Yes",0,F121-G121) -> 0 | I121: =IF(E121="Yes","Void",IF(H121<=0,"Paid",IF(G121>0,"Partially Paid","Issued"))) -> Paid
A122: INV-2609-015 | B122: S1015 | C122: 46266 | D122: 46272 | F122: =SUMIFS('Invoice Lines'!$G$2:$G$319,'Invoice Lines'!$A$2:$A$319,A122) -> 300 | G122: =SUMIFS(Receipts!$D$2:$D$149,Receipts!$B$2:$B$149,A122) -> 0 | H122: =IF(E122="Yes",0,F122-G122) -> 300 | I122: =IF(E122="Yes","Void",IF(H122<=0,"Paid",IF(G122>0,"Partially Paid","Issued"))) -> Issued
A123: INV-2609-016 | B123: S1016 | C123: 46266 | D123: 46272 | F123: =SUMIFS('Invoice Lines'!$G$2:$G$319,'Invoice Lines'!$A$2:$A$319,A123) -> 300 | G123: =SUMIFS(Receipts!$D$2:$D$149,Receipts!$B$2:$B$149,A123) -> 300 | H123: =IF(E123="Yes",0,F123-G123) -> 0 | I123: =IF(E123="Yes","Void",IF(H123<=0,"Paid",IF(G123>0,"Partially Paid","Issued"))) -> Paid
A124: INV-2609-017 | B124: S1017 | C124: 46266 | D124: 46272 | F124: =SUMIFS('Invoice Lines'!$G$2:$G$319,'Invoice Lines'!$A$2:$A$319,A124) -> 360 | G124: =SUMIFS(Receipts!$D$2:$D$149,Receipts!$B$2:$B$149,A124) -> 360 | H124: =IF(E124="Yes",0,F124-G124) -> 0 | I124: =IF(E124="Yes","Void",IF(H124<=0,"Paid",IF(G124>0,"Partially Paid","Issued"))) -> Paid
A125: INV-2609-018 | B125: S1018 | C125: 46266 | D125: 46272 | F125: =SUMIFS('Invoice Lines'!$G$2:$G$319,'Invoice Lines'!$A$2:$A$319,A125) -> 240 | G125: =SUMIFS(Receipts!$D$2:$D$149,Receipts!$B$2:$B$149,A125) -> 240 | H125: =IF(E125="Yes",0,F125-G125) -> 0 | I125: =IF(E125="Yes","Void",IF(H125<=0,"Paid",IF(G125>0,"Partially Paid","Issued"))) -> Paid
A126: INV-2609-019 | B126: S1019 | C126: 46266 | D126: 46272 | F126: =SUMIFS('Invoice Lines'!$G$2:$G$319,'Invoice Lines'!$A$2:$A$319,A126) -> 360 | G126: =SUMIFS(Receipts!$D$2:$D$149,Receipts!$B$2:$B$149,A126) -> 360 | H126: =IF(E126="Yes",0,F126-G126) -> 0 | I126: =IF(E126="Yes","Void",IF(H126<=0,"Paid",IF(G126>0,"Partially Paid","Issued"))) -> Paid
A127: INV-2609-020 | B127: S1020 | C127: 46266 | D127: 46272 | E127: Yes | F127: =SUMIFS('Invoice Lines'!$G$2:$G$319,'Invoice Lines'!$A$2:$A$319,A127) -> 180 | G127: =SUMIFS(Receipts!$D$2:$D$149,Receipts!$B$2:$B$149,A127) -> 0 | H127: =IF(E127="Yes",0,F127-G127) -> 0 | I127: =IF(E127="Yes","Void",IF(H127<=0,"Paid",IF(G127>0,"Partially Paid","Issued"))) -> Void
A128: INV-2609-021 | B128: S1021 | C128: 46266 | D128: 46272 | E128: Yes | F128: =SUMIFS('Invoice Lines'!$G$2:$G$319,'Invoice Lines'!$A$2:$A$319,A128) -> 540 | G128: =SUMIFS(Receipts!$D$2:$D$149,Receipts!$B$2:$B$149,A128) -> 0 | H128: =IF(E128="Yes",0,F128-G128) -> 0 | I128: =IF(E128="Yes","Void",IF(H128<=0,"Paid",IF(G128>0,"Partially Paid","Issued"))) -> Void
A129: INV-2609-022 | B129: S1022 | C129: 46266 | D129: 46272 | F129: =SUMIFS('Invoice Lines'!$G$2:$G$319,'Invoice Lines'!$A$2:$A$319,A129) -> 360 | G129: =SUMIFS(Receipts!$D$2:$D$149,Receipts!$B$2:$B$149,A129) -> 360 | H129: =IF(E129="Yes",0,F129-G129) -> 0 | I129: =IF(E129="Yes","Void",IF(H129<=0,"Paid",IF(G129>0,"Partially Paid","Issued"))) -> Paid
A130: INV-2609-023 | B130: S1023 | C130: 46266 | D130: 46272 | E130: Yes | F130: =SUMIFS('Invoice Lines'!$G$2:$G$319,'Invoice Lines'!$A$2:$A$319,A130) -> 240 | G130: =SUMIFS(Receipts!$D$2:$D$149,Receipts!$B$2:$B$149,A130) -> 0 | H130: =IF(E130="Yes",0,F130-G130) -> 0 | I130: =IF(E130="Yes","Void",IF(H130<=0,"Paid",IF(G130>0,"Partially Paid","Issued"))) -> Void
A131: INV-2609-024 | B131: S1024 | C131: 46266 | D131: 46272 | F131: =SUMIFS('Invoice Lines'!$G$2:$G$319,'Invoice Lines'!$A$2:$A$319,A131) -> 150 | G131: =SUMIFS(Receipts!$D$2:$D$149,Receipts!$B$2:$B$149,A131) -> 150 | H131: =IF(E131="Yes",0,F131-G131) -> 0 | I131: =IF(E131="Yes","Void",IF(H131<=0,"Paid",IF(G131>0,"Partially Paid","Issued"))) -> Paid
A132: INV-2609-025 | B132: S1025 | C132: 46266 | D132: 46272 | E132: Yes | F132: =SUMIFS('Invoice Lines'!$G$2:$G$319,'Invoice Lines'!$A$2:$A$319,A132) -> 120 | G132: =SUMIFS(Receipts!$D$2:$D$149,Receipts!$B$2:$B$149,A132) -> 0 | H132: =IF(E132="Yes",0,F132-G132) -> 0 | I132: =IF(E132="Yes","Void",IF(H132<=0,"Paid",IF(G132>0,"Partially Paid","Issued"))) -> Void
A133: INV-2609-026 | B133: S1026 | C133: 46266 | D133: 46272 | F133: =SUMIFS('Invoice Lines'!$G$2:$G$319,'Invoice Lines'!$A$2:$A$319,A133) -> 180 | G133: =SUMIFS(Receipts!$D$2:$D$149,Receipts!$B$2:$B$149,A133) -> 90 | H133: =IF(E133="Yes",0,F133-G133) -> 90 | I133: =IF(E133="Yes","Void",IF(H133<=0,"Paid",IF(G133>0,"Partially Paid","Issued"))) -> Partially Paid
A134: INV-2609-027 | B134: S1027 | C134: 46266 | D134: 46272 | F134: =SUMIFS('Invoice Lines'!$G$2:$G$319,'Invoice Lines'!$A$2:$A$319,A134) -> 360 | G134: =SUMIFS(Receipts!$D$2:$D$149,Receipts!$B$2:$B$149,A134) -> 360 | H134: =IF(E134="Yes",0,F134-G134) -> 0 | I134: =IF(E134="Yes","Void",IF(H134<=0,"Paid",IF(G134>0,"Partially Paid","Issued"))) -> Paid
A135: INV-2609-028 | B135: S1028 | C135: 46266 | D135: 46272 | F135: =SUMIFS('Invoice Lines'!$G$2:$G$319,'Invoice Lines'!$A$2:$A$319,A135) -> 540 | G135: =SUMIFS(Receipts!$D$2:$D$149,Receipts!$B$2:$B$149,A135) -> 540 | H135: =IF(E135="Yes",0,F135-G135) -> 0 | I135: =IF(E135="Yes","Void",IF(H135<=0,"Paid",IF(G135>0,"Partially Paid","Issued"))) -> Paid
A136: INV-2609-029 | B136: S1029 | C136: 46266 | D136: 46272 | F136: =SUMIFS('Invoice Lines'!$G$2:$G$319,'Invoice Lines'!$A$2:$A$319,A136) -> 540 | G136: =SUMIFS(Receipts!$D$2:$D$149,Receipts!$B$2:$B$149,A136) -> 540 | H136: =IF(E136="Yes",0,F136-G136) -> 0 | I136: =IF(E136="Yes","Void",IF(H136<=0,"Paid",IF(G136>0,"Partially Paid","Issued"))) -> Paid
A137: INV-2609-030 | B137: S1030 | C137: 46266 | D137: 46272 | E137: Yes | F137: =SUMIFS('Invoice Lines'!$G$2:$G$319,'Invoice Lines'!$A$2:$A$319,A137) -> 240 | G137: =SUMIFS(Receipts!$D$2:$D$149,Receipts!$B$2:$B$149,A137) -> 0 | H137: =IF(E137="Yes",0,F137-G137) -> 0 | I137: =IF(E137="Yes","Void",IF(H137<=0,"Paid",IF(G137>0,"Partially Paid","Issued"))) -> Void
A138: INV-2609-031 | B138: S1031 | C138: 46266 | D138: 46272 | F138: =SUMIFS('Invoice Lines'!$G$2:$G$319,'Invoice Lines'!$A$2:$A$319,A138) -> 120 | G138: =SUMIFS(Receipts!$D$2:$D$149,Receipts!$B$2:$B$149,A138) -> 120 | H138: =IF(E138="Yes",0,F138-G138) -> 0 | I138: =IF(E138="Yes","Void",IF(H138<=0,"Paid",IF(G138>0,"Partially Paid","Issued"))) -> Paid
A139: INV-2609-032 | B139: S1032 | C139: 46266 | D139: 46272 | F139: =SUMIFS('Invoice Lines'!$G$2:$G$319,'Invoice Lines'!$A$2:$A$319,A139) -> 120 | G139: =SUMIFS(Receipts!$D$2:$D$149,Receipts!$B$2:$B$149,A139) -> 120 | H139: =IF(E139="Yes",0,F139-G139) -> 0 | I139: =IF(E139="Yes","Void",IF(H139<=0,"Paid",IF(G139>0,"Partially Paid","Issued"))) -> Paid
A140: INV-2609-033 | B140: S1033 | C140: 46266 | D140: 46272 | F140: =SUMIFS('Invoice Lines'!$G$2:$G$319,'Invoice Lines'!$A$2:$A$319,A140) -> 360 | G140: =SUMIFS(Receipts!$D$2:$D$149,Receipts!$B$2:$B$149,A140) -> 360 | H140: =IF(E140="Yes",0,F140-G140) -> 0 | I140: =IF(E140="Yes","Void",IF(H140<=0,"Paid",IF(G140>0,"Partially Paid","Issued"))) -> Paid
A141: INV-2609-034 | B141: S1034 | C141: 46266 | D141: 46272 | F141: =SUMIFS('Invoice Lines'!$G$2:$G$319,'Invoice Lines'!$A$2:$A$319,A141) -> 360 | G141: =SUMIFS(Receipts!$D$2:$D$149,Receipts!$B$2:$B$149,A141) -> 360 | H141: =IF(E141="Yes",0,F141-G141) -> 0 | I141: =IF(E141="Yes","Void",IF(H141<=0,"Paid",IF(G141>0,"Partially Paid","Issued"))) -> Paid
A142: INV-2609-035 | B142: S1035 | C142: 46266 | D142: 46272 | F142: =SUMIFS('Invoice Lines'!$G$2:$G$319,'Invoice Lines'!$A$2:$A$319,A142) -> 360 | G142: =SUMIFS(Receipts!$D$2:$D$149,Receipts!$B$2:$B$149,A142) -> 0 | H142: =IF(E142="Yes",0,F142-G142) -> 360 | I142: =IF(E142="Yes","Void",IF(H142<=0,"Paid",IF(G142>0,"Partially Paid","Issued"))) -> Issued
...

Sheet Invoice Lines
A1: Invoice No | B1: Line | C1: Subject | D1: Description | E1: Qty | F1: Unit Fee | G1: Line Total
A2: INV-2607-001 | B2: 1 | C2: Mathematics | D2: Mathematics – Form 1 – Jul 2026 (4 classes) | E2: 1 | F2: 150 | G2: =E2*F2 -> 150
A3: INV-2607-001 | B3: 2 | C3: English | D3: English – Form 1 – Jul 2026 (4 classes) | E3: 1 | F3: 150 | G3: =E3*F3 -> 150
A4: INV-2607-002 | B4: 1 | C4: English | D4: English – Form 5 – Jul 2026 (4 classes) | E4: 1 | F4: 180 | G4: =E4*F4 -> 180
A5: INV-2607-003 | B5: 1 | C5: English | D5: English – Form 1 – Jul 2026 (4 classes) | E5: 1 | F5: 150 | G5: =E5*F5 -> 150
A6: INV-2607-003 | B6: 2 | C6: Bahasa Melayu | D6: Bahasa Melayu – Form 1 – Jul 2026 (4 classes) | E6: 1 | F6: 150 | G6: =E6*F6 -> 150
A7: INV-2607-004 | B7: 1 | C7: English | D7: English – Form 5 – Jul 2026 (4 classes) | E7: 1 | F7: 180 | G7: =E7*F7 -> 180
A8: INV-2607-005 | B8: 1 | C8: Mathematics | D8: Mathematics – Std 6 – Jul 2026 (4 classes) | E8: 1 | F8: 120 | G8: =E8*F8 -> 120
A9: INV-2607-005 | B9: 2 | C9: Chinese | D9: Chinese – Std 6 – Jul 2026 (4 classes) | E9: 1 | F9: 120 | G9: =E9*F9 -> 120
A10: INV-2607-006 | B10: 1 | C10: Mathematics | D10: Mathematics – Form 2 – Jul 2026 (4 classes) | E10: 1 | F10: 150 | G10: =E10*F10 -> 150
A11: INV-2607-007 | B11: 1 | C11: Chinese | D11: Chinese – Std 4 – Jul 2026 (4 classes) | E11: 1 | F11: 120 | G11: =E11*F11 -> 120
A12: INV-2607-008 | B12: 1 | C12: Bahasa Melayu | D12: Bahasa Melayu – Std 4 – Jul 2026 (4 classes) | E12: 1 | F12: 120 | G12: =E12*F12 -> 120
A13: INV-2607-008 | B13: 2 | C13: Chinese | D13: Chinese – Std 4 – Jul 2026 (4 classes) | E13: 1 | F13: 120 | G13: =E13*F13 -> 120
... A319: INV-2609-056 | B319: 2 | C319: Add Maths | D319: Add Maths – Form 5 – Sep 2026 (4 classes) | E319: 1 | F319: 180 | G319: =E319*F319 -> 180

Sheet Receipts
A1: Receipt No | B1: Invoice No | C1: Received On | D1: Amount | E1: Method
A2: RC-00001 | B2: INV-2607-001 | C2: 46213 | D2: 300 | E2: Cash
A3: RC-00002 | B3: INV-2607-002 | C3: 46207 | D3: 180 | E3: DuitNow
A4: RC-00003 | B4: INV-2607-003 | C4: 46218 | D4: 300 | E4: Cheque
A5: RC-00004 | B5: INV-2607-004 | C5: 46205 | D5: 180 | E5: Cheque
A6: RC-00005 | B6: INV-2607-005 | C6: 46206 | D6: 240 | E6: Cash
A7: RC-00006 | B7: INV-2607-006 | C7: 46209 | D7: 150 | E7: Cash
A8: RC-00007 | B8: INV-2607-007 | C8: 46205 | D8: 120 | E8: Cash
A9: RC-00008 | B9: INV-2607-008 | C9: 46210 | D9: 240 | E9: Cash
A10: RC-00009 | B10: INV-2607-009 | C10: 46206 | D10: 360 | E10: Cash
A11: RC-00010 | B11: INV-2607-010 | C11: 46205 | D11: 150 | E11: Cheque
A12: RC-00011 | B12: INV-2607-011 | C12: 46224 | D12: 540 | E12: Cash
A13: RC-00012 | B13: INV-2607-012 | C13: 46205 | D13: 360 | E13: Online transfer
... A149: RC-00148 | B149: INV-2609-054 | C149: 46269 | D149: 150 | E149: Cash

Sheet Classes
A1: Session | B1: Date | C1: Subject | D1: Level | E1: Tutor | F1: Enrolled | G1: Present | H1: Room
A2: CL-0001 | B2: 46267 | C2: English | D2: Form 2 | E2: Ms Sarah | F2: 1 | G2: 0 | H2: Room B
A3: CL-0002 | B3: 46267 | C3: English | D3: Std 4 | E3: Ms Sarah | F3: 2 | G3: 1 | H3: Room B
A4: CL-0003 | B4: 46269 | C4: English | D4: Form 3 | E4: Ms Sarah | F4: 2 | G4: 0 | H4: Room A
A5: CL-0004 | B5: 46270 | C5: Mathematics | D5: Form 2 | E5: Ms Wong | F5: 2 | G5: 0 | H5: Online
A6: CL-0005 | B6: 46270 | C6: Bahasa Melayu | D6: Form 1 | E6: Cikgu Aina | F6: 1 | G6: 0 | H6: Room B
A7: CL-0006 | B7: 46272 | C7: Mathematics | D7: Std 6 | E7: Ms Wong | F7: 3 | G7: 2 | H7: Room C
A8: CL-0007 | B8: 46274 | C8: Chinese | D8: Std 6 | E8: 陈老师 | F8: 4 | G8: 2 | H8: Online
A9: CL-0008 | B9: 46275 | C9: Mathematics | D9: Form 5 | E9: Ms Wong | F9: 3 | G9: 3 | H9: Room B
A10: CL-0009 | B10: 46276 | C10: Chinese | D10: Std 4 | E10: 陈老师 | F10: 5 | G10: 5 | H10: Room A
A11: CL-0010 | B11: 46277 | C11: Chinese | D11: Std 5 | E11: 陈老师 | F11: 3 | G11: 1 | H11: Online
A12: CL-0011 | B12: 46279 | C12: English | D12: Std 6 | E12: Ms Sarah | F12: 2 | G12: 0 | H12: Online
A13: CL-0012 | B13: 46279 | C13: Bahasa Melayu | D13: Std 6 | E13: Cikgu Aina | F13: 2 | G13: 2 | H13: Online
... A31: CL-0030 | B31: 46289 | C31: Chinese | D31: Std 5 | E31: 陈老师 | F31: 3 | G31: 1 | H31: Online
